import React, {useState} from "react";
import {useErrorHandler, withErrorBoundary} from "../lib/ErrorBoundary";
import {ErrorFallback} from "../utils";

function SimpleExample2() {

  let [number, setNumber] = useState(0);
  let handleError = useErrorHandler();

  const onAddNumber = () => {
    setNumber(number + 1);
  }

  // Warning: Can not catch this error with Error Boundary!!!
  // This is Event handlers, we should use try catch!!!
  const onThrowError = () => {
    // try {
    //   throw new Error(`when number is ${number}, throw an error`);
    // } catch (e: any) {
    //   handleError(e);
    // }
    setTimeout(() => {
      handleError(new Error('üí• CABOOM üí•'))
    })
  }

  if (number > 5) {
    throw new Error(`when number is ${number}, throw an error`);
  }
  return (
    <>
      <div>Number: {number}
      </div>
      <input type="button" value="click" onClick={onAddNumber}/>
      <input type="button" value="throw error" onClick={onThrowError}/>
    </>
  )
}

const WithErrorBoundarySimpleExample2 = withErrorBoundary(SimpleExample2, {
  onError: () => console.error('Âá∫ÈîôÂï¶'),
  onReset: () => console.log('Â∑≤ÁªèÈáçÁΩÆ'),
  FallbackComponent: ErrorFallback,
});

export default WithErrorBoundarySimpleExample2;
